<?xml version="1.0"?>
<robot name="scout_mini" xmlns:xacro="http://ros.org/wiki/xacro">
    
    <!-- Base link -->
    <link name="base_link">
        <visual>
            <origin xyz="0 0 0" rpy="1.57 0 -1.57" />
            <geometry>
                <mesh filename="package://my_scout_description/meshes/scout_mini_base_link.dae" />
            </geometry>
        </visual>
        <collision>
            <origin xyz="0 0 0" rpy="1.57 0 -1.57" />
            <geometry>
                <mesh filename="package://my_scout_description/meshes/scout_mini_base_link.dae" />
            </geometry>
        </collision>
    </link>

    <!-- Inertial link -->
    <link name="inertial_link">
        <inertial>
            <mass value="132.3898489950015" />
            <origin xyz="0 0 0" />
            <inertia ixx="0.185196122711036" ixy="4.30144213829512E-08" ixz="5.81037523686401E-08"
                     iyy="0.364893736238929" iyz="-0.000386720198091934" izz="0.223868521722778" />
        </inertial>
    </link>

    <joint name="inertial_joint" type="fixed">
        <origin xyz="0 0 0" rpy="0 0 0" />
        <parent link="base_link" />
        <child link="inertial_link" />
    </joint>

    <!-- Front Right Wheel -->
    <link name="front_right_wheel_link">
        <inertial>
            <mass value="3" />
            <origin xyz="0 0 0" />
            <inertia ixx="0.7171" ixy="0" ixz="0" iyy="0.7171" iyz="0" izz="0.1361" />
        </inertial>
        <visual>
            <origin xyz="0 0 0" rpy="0 0 0" />
            <geometry>
                <mesh filename="package://my_scout_description/meshes/wheel.dae" />
            </geometry>
        </visual>
        <collision>
            <origin xyz="0 0 0" rpy="0 0 0" />
            <geometry>
                <mesh filename="package://my_scout_description/meshes/wheel.dae" />
            </geometry>
        </collision>
    </link>

    <joint name="front_right_wheel" type="continuous">
        <origin rpy="1.57 0 0" xyz="0.2319755 -0.2082515 -0.099998" />
        <parent link="base_link" />
        <child link="front_right_wheel_link" />
        <axis xyz="0 0 -1" rpy="0 0 0" />
    </joint>

    <!-- Front Left Wheel -->
    <link name="front_left_wheel_link">
        <inertial>
            <mass value="3" />
            <origin xyz="0 0 0" />
            <inertia ixx="0.7171" ixy="0" ixz="0" iyy="0.7171" iyz="0" izz="0.1361" />
        </inertial>
        <visual>
            <origin xyz="0 0 0" rpy="0 0 0" />
            <geometry>
                <mesh filename="package://my_scout_description/meshes/wheel.dae" />
            </geometry>
        </visual>
        <collision>
            <origin xyz="0 0 0" rpy="0 0 0" />
            <geometry>
                <mesh filename="package://my_scout_description/meshes/wheel.dae" />
            </geometry>
        </collision>
    </link>

    <joint name="front_left_wheel" type="continuous">
        <origin rpy="-1.57 0 0" xyz="0.2319755 0.2082515 -0.100998" />
        <parent link="base_link" />
        <child link="front_left_wheel_link" />
        <axis xyz="0 0 1" rpy="0 0 0" />
    </joint>

    <!-- Rear Right Wheel -->
    <link name="rear_right_wheel_link">
        <inertial>
            <mass value="3" />
            <origin xyz="0 0 0" />
            <inertia ixx="0.7171" ixy="0" ixz="0" iyy="0.7171" iyz="0" izz="0.1361" />
        </inertial>
        <visual>
            <origin xyz="0 0 0" rpy="0 0 0" />
            <geometry>
                <mesh filename="package://my_scout_description/meshes/wheel.dae" />
            </geometry>
        </visual>
        <collision>
            <origin xyz="0 0 0" rpy="0 0 0" />
            <geometry>
                <mesh filename="package://my_scout_description/meshes/wheel.dae" />
            </geometry>
        </collision>
    </link>

    <joint name="rear_right_wheel" type="continuous">
        <origin rpy="1.57 0 0" xyz="-0.2319755 -0.2082515 -0.099998" />
        <parent link="base_link" />
        <child link="rear_right_wheel_link" />
        <axis xyz="0 0 -1" rpy="0 0 0" />
    </joint>

    <!-- Rear Left Wheel -->
    <link name="rear_left_wheel_link">
        <inertial>
            <mass value="3" />
            <origin xyz="0 0 0" />
            <inertia ixx="0.7171" ixy="0" ixz="0" iyy="0.7171" iyz="0" izz="0.1361" />
        </inertial>
        <visual>
            <origin xyz="0 0 0" rpy="0 0 0" />
            <geometry>
                <mesh filename="package://my_scout_description/meshes/wheel.dae" />
            </geometry>
        </visual>
        <collision>
            <origin xyz="0 0 0" rpy="0 0 0" />
            <geometry>
                <mesh filename="package://my_scout_description/meshes/wheel.dae" />
            </geometry>
        </collision>
    </link>

    <joint name="rear_left_wheel" type="continuous">
        <origin rpy="-1.57 0 0" xyz="-0.2319755 0.2082515 -0.100998" />
        <parent link="base_link" />
        <child link="rear_left_wheel_link" />
        <axis xyz="0 0 1" rpy="0 0 0" />
    </joint>


    <!-- LiDAR Sensor -->
    <link name="lidar_link">
        <inertial>
            <mass value="0.1"/>
            <origin xyz="0 0 0"/>
            <inertia ixx="0.0001" ixy="0" ixz="0" iyy="0.0001" iyz="0" izz="0.0001"/>
        </inertial>
        <visual>
            <origin xyz="0 0 0" rpy="0 0 0"/>
            <geometry>
                <cylinder radius="0.05" length="0.07"/>
            </geometry>
            <material name="black">
                <color rgba="0.1 0.1 0.1 1"/>
            </material>
        </visual>
        <collision>
            <origin xyz="0 0 0" rpy="0 0 0"/>
            <geometry>
                <cylinder radius="0.05" length="0.07"/>
            </geometry>
        </collision>
    </link>

    <joint name="lidar_joint" type="fixed">
        <!-- Mount on top-front of base_link -->
        <origin xyz="0.15 0 0.15" rpy="0 0 0"/>
        <parent link="base_link"/>
        <child link="lidar_link"/>
    </joint>
      
      <!-- LiDAR Plugin -->
    <gazebo reference="lidar_link">
      <sensor name="lidar" type="gpu_lidar">
         <topic>scan</topic>
         <ignition_frame_id>lidar_link</ignition_frame_id>  <!-- ADD THIS LINE -->
         <update_rate>7</update_rate>
         <lidar>
            <scan>
                <horizontal>
                    <samples>360</samples>
                    <resolution>1</resolution>
                    <min_angle>-3.14159</min_angle>
                    <max_angle>3.14159</max_angle>
                </horizontal>
            </scan>
            <range>
                <min>0.12</min>
                <max>10.0</max>
                <resolution>0.01</resolution>
            </range>
            <noise>
                <type>gaussian</type>
                <mean>0.0</mean>
                <stddev>0.01</stddev>
            </noise>
         </lidar>
         <always_on>1</always_on>
         <visualize>true</visualize>
     </sensor>
    </gazebo>

        <!-- Camera Sensor -->
    <link name="camera_link">
        <inertial>
            <mass value="0.1"/>
            <origin xyz="0 0 0"/>
            <inertia ixx="0.0001" ixy="0" ixz="0" iyy="0.0001" iyz="0" izz="0.0001"/>
        </inertial>
        <visual>
            <origin xyz="0 0 0" rpy="0 0 0"/>
            <geometry>
                <box size="0.05 0.05 0.05"/>
            </geometry>
            <material name="blue">
                <color rgba="0.0 0.0 0.8 1"/>
            </material>
        </visual>
        <collision>
            <origin xyz="0 0 0" rpy="0 0 0"/>
            <geometry>
                <box size="0.05 0.05 0.05"/>
            </geometry>    
        </collision>
    </link>

    <joint name="camera_joint" type="fixed">
        <!-- Mount on front of base_link, slightly lower than LiDAR -->
        <origin xyz="0.20 0 0.10" rpy="0 0 0"/>
        <parent link="base_link"/>
        <child link="camera_link"/>
    </joint>


    <!-- Camera Plugin -->
    <gazebo reference="camera_link">
        <sensor name="camera" type="camera">
            <topic>camera</topic>
            <ignition_frame_id>camera_link</ignition_frame_id>
            <update_rate>15</update_rate>
            <camera>
                <horizontal_fov>1.047</horizontal_fov>
                <image>
                    <width>640</width>
                    <height>480</height>
                    <format>R8G8B8</format>
                </image>
                <clip>
                    <near>0.1</near>
                    <far>100</far>
                </clip>
                <noise>
                    <type>gaussian</type>
                    <mean>0.0</mean>
                    <stddev>0.007</stddev>
                </noise>
            </camera>
            <always_on>1</always_on>
            <visualize>true</visualize>
        </sensor>
    </gazebo>



    <!-- Gazebo plugins -->
    <gazebo>
        <plugin filename="libignition-gazebo-joint-state-publisher-system.so"
                name="ignition::gazebo::systems::JointStatePublisher">
            <topic>joint_states</topic>
            <update_rate>50</update_rate>
            <joint_name>front_right_wheel</joint_name>
            <joint_name>front_left_wheel</joint_name>
            <joint_name>rear_right_wheel</joint_name>
            <joint_name>rear_left_wheel</joint_name>
        </plugin>


        <plugin filename="libignition-gazebo-diff-drive-system.so"
                name="ignition::gazebo::systems::DiffDrive">
            <left_joint>front_left_wheel</left_joint>
            <right_joint>front_right_wheel</right_joint>
            <left_joint>rear_left_wheel</left_joint>
            <right_joint>rear_right_wheel</right_joint>
            <wheel_separation>0.58</wheel_separation>
            <wheel_radius>0.08</wheel_radius>
            <max_wheel_torque>20</max_wheel_torque>
            <max_linear_acceleration>1.0</max_linear_acceleration>
            <topic>cmd_vel</topic>
            <odom_topic>odom</odom_topic>
            <tf_topic>tf</tf_topic>
            <odom_publish_frequency>50</odom_publish_frequency>
            <frame_id>odom</frame_id>
            <child_frame_id>base_link</child_frame_id>
        </plugin>
    </gazebo>
</robot>